2025-06-15 13:10:42,042 - ERROR - An exception occurred
Traceback (most recent call last):
  File "src/exception.py", line 35, in <module>
    result = 1 / 0
ZeroDivisionError: division by zero
